# Specific vs General Exception Handling in C#

In C#, handling exceptions properly is crucial for writing robust and maintainable code. One important best practice is to prefer **specific exceptions** over catching general exceptions.

## 1️⃣ Specific Exception Handling

Catching a specific exception means handling only the type of error you expect. For example:

```csharp
try
{
    int result = 10 / divisor;
}
catch (DivideByZeroException ex)  // Specific Exception
{
    Console.WriteLine("Cannot divide by zero!");
}
```

**Advantages:**
- You know exactly which error occurred.
- You can provide meaningful messages to the user.
- Easier to debug and maintain.
- Avoids hiding unexpected issues.

## 2️⃣ General Exception Handling

Catching a general exception uses the `Exception` type:

```csharp
try
{
    int result = 10 / divisor;
}
catch (Exception ex)  // General Exception
{
    Console.WriteLine("An error occurred!");
}
```

**Disadvantages:**
- Hides the specific cause of the error.
- Harder to debug.
- May catch exceptions you didn't intend to handle, masking bugs.

## 3️⃣ Best Practices

- Always prefer **specific exceptions** for predictable errors.
- Use general exceptions only for unexpected or unforeseen errors.
- Always log exceptions for debugging purposes, whether specific or general.
- Provide meaningful feedback to the user when appropriate.

## 4️⃣ Example Summary

**Good Approach:**
```csharp
try
{
    int result = 10 / divisor;
}
catch (DivideByZeroException ex)
{
    Console.WriteLine("Cannot divide by zero!");
}
```

**When to use General Exception:**
```csharp
try
{
    // Some risky code
}
catch (Exception ex)
{
    // Log unexpected errors
}
```

> Using specific exceptions helps improve code clarity, maintainability, and user feedback. General exceptions are a fallback for unpredicted errors.
---

## This example demonstrates a simpler, non-professional exception handling approach:

```csharp
using System;

class Program
{
    static void Main()
    {
        int[] numbers = { 10, 20, 0, 5 };
        
        foreach (var num in numbers)
        {
            try
            {
                int result = DivideByNumber(100, num);
                Console.WriteLine($"100 / {num} = {result}");
            }
            catch (DivideByZeroException ex)
            {
                Console.WriteLine($"Cannot divide by zero! Value: {num}");
            }
            catch (ArgumentOutOfRangeException ex)
            {
                Console.WriteLine($"Invalid index or value: {num}");
            }
            catch (Exception ex) // General exception as a safety net
            {
                Console.WriteLine($"Unexpected error: {ex.Message}");
            }
        }

        try
        {
            int value = GetArrayValue(numbers, 10); // Intentionally out of range
            Console.WriteLine($"Value at index 10: {value}");
        }
        catch (ArgumentOutOfRangeException ex)
        {
            Console.WriteLine("Caught out of range exception when accessing array!");
        }
    }

    static int DivideByNumber(int dividend, int divisor)
    {
        if (divisor < 0)
            throw new ArgumentOutOfRangeException(nameof(divisor), "Divisor cannot be negative");

        return dividend / divisor;
    }

    static int GetArrayValue(int[] array, int index)
    {
        if (index < 0 || index >= array.Length)
            throw new ArgumentOutOfRangeException(nameof(index), "Index out of bounds");

        return array[index];
    }
}
```

- Each function (DivideByNumber, GetArrayValue) does not handle its own exceptions internally.

- Instead, all exceptions are propagated to the Main method, where multiple specific exceptions (DivideByZeroException, ArgumentOutOfRangeException) are caught.

- A general Exception catch acts as a safety net for any unexpected errors.

- The advantage of this approach is simplicity and fewer lines of code inside functions.

- The disadvantage is that Main becomes responsible for all error handling, which can make it long, harder to maintain, and less modular.

- Functions do not log errors or provide context-specific messages; all handling logic is centralized in Main.

- In contrast, a professional approach would let each function handle predictable exceptions internally, log them appropriately, and leave only unexpected errors to be handled by Main.

---

# Best Practices for Exception Handling in Professional Projects

In professional projects, the following practices are commonly followed for exception handling:

## 1️⃣ Specific Exceptions Take Priority

For each operation that may throw an error, developers try to catch **specific exceptions**.

**Examples:** `DivideByZeroException`, `FileNotFoundException`, `SqlException`, etc.

**Advantages:**
- You can precisely identify what went wrong.
- Enables appropriate corrective actions.

## 2️⃣ General Exception Only as a Last Resort or for Logging

Usually, a `catch (Exception ex)` is placed at the highest level of the application to ensure no exception is missed.

- This general catch is typically used **only for logging and notification**, not for handling specific errors.

## 3️⃣ Detailed Logging

All exceptions are logged (e.g., using Serilog, NLog, or ELK stack).

- Logs usually include:
  - Error message
  - Stack trace
  - Timestamp
  - Context information

## 4️⃣ User-Friendly Messages

End users never see technical error details.

- Only clear and understandable messages are displayed, e.g.:
  - “Cannot divide by zero”
  - “File not found”

## 5️⃣ Monitoring and Alerts

Monitoring systems (e.g., Application Insights, Sentry, Datadog) collect errors and send alerts to the team.

- Helps in quickly identifying and addressing issues in production.

This example demonstrates professional-level exception handling in C#, using multiple specific exceptions along with a final general exception for robust and maintainable code.

## Key Features of this Example

- **Specific Exceptions** for each type of operation:
  - `DivideByZeroException` for division operations
  - `FileNotFoundException` and `IOException` for file operations
  - `SqlException` for database queries

- **General Exception** in `Main` for final catch:
  - Ensures any unexpected errors are logged and handled gracefully

- **LogError Method**:
  - Centralized logging without exposing technical details to the user
  - Can be replaced by professional logging frameworks like Serilog or NLog

- **User-Friendly Messages**:
  - Users receive clear and meaningful messages without seeing stack traces or internal details

- **Separation of Operations**:
  - Division, array processing, file reading, and database access are in separate methods
  - Keeps code clean, readable, and maintainable

## Example Code

```csharp
using System;
using System.IO;
using System.Data.SqlClient;

class Program
{
    static void Main()
    {
        int[] numbers = { 10, 20, 30 };
        try
        {
            // Example 1: Division
            DivideNumbers(10, 0);

            // Example 2: Deliberate DivideByZero and IndexOutOfRange
            ProcessArray(numbers, 0, 5); 

            // Example 3: Reading a file
            ReadFile("nonexistentfile.txt");

            // Example 4: Database query
            ExecuteDatabaseQuery("SELECT * FROM NonexistentTable");
        }
        catch (Exception ex)
        {
            // General Exception for final catch
            LogError(ex);
            Console.WriteLine("An unexpected error occurred. Please contact support.");
        }
    }

    static void DivideNumbers(int a, int b)
    {
        try
        {
            if (b < 0)
                throw new ArgumentOutOfRangeException(nameof(b), "Divisor cannot be negative");
    
            int result = a / b;
            Console.WriteLine($"Result: {result}");
        }
        catch (DivideByZeroException ex)
        {
            LogError(ex);
            Console.WriteLine("Cannot divide by zero!");
        }
        catch (ArgumentOutOfRangeException ex)
        {
            LogError(ex);
            Console.WriteLine("Divisor cannot be negative!");
        }
    }

    static void ProcessArray(int[] arr, int divisor, int accessIndex)
    {
        try
        {
            int divisionResult = arr[0] / divisor;
            Console.WriteLine($"Division result: {divisionResult}");

            int value = arr[accessIndex];
            Console.WriteLine($"Accessed value: {value}");
        }
        catch (DivideByZeroException ex)
        {
            LogError(ex);
            Console.WriteLine("Error: Cannot divide by zero!");
        }
        catch (IndexOutOfRangeException ex)
        {
            LogError(ex);
            Console.WriteLine("Error: Array index is out of range!");
        }
        catch (NullReferenceException ex)
        {
            LogError(ex);
            Console.WriteLine("Error: Array is null!");
        }
    }

    static void ReadFile(string path)
    {
        try
        {
            string content = File.ReadAllText(path);
            Console.WriteLine(content);
        }
        catch (FileNotFoundException ex)
        {
            LogError(ex);
            Console.WriteLine($"File not found: {path}");
        }
        catch (IOException ex)
        {
            LogError(ex);
            Console.WriteLine("An I/O error occurred while reading the file.");
        }
    }

    static void ExecuteDatabaseQuery(string query)
    {
        try
        {
            using (SqlConnection conn = new SqlConnection("YourConnectionString"))
            {
                conn.Open();
                SqlCommand cmd = new SqlCommand(query, conn);
                SqlDataReader reader = cmd.ExecuteReader();
                while (reader.Read())
                {
                    Console.WriteLine(reader[0]);
                }
            }
        }
        catch (SqlException ex)
        {
            LogError(ex);
            Console.WriteLine("Database query failed. Please check your query or connection.");
        }
    }

    static void LogError(Exception ex)
    {
        // In real projects, you can use Serilog or NLog here
        Console.WriteLine($"[LOG] {DateTime.Now}: {ex.GetType().Name} - {ex.Message}");
    }
}
```
> This structure demonstrates how to handle multiple specific exceptions for predictable errors while using a final general exception to catch anything unexpected. It also emphasizes clean separation of operations and professional logging practices.

# Key Differences Between This Non-Professional Sample and “Professional In-Function Exception Handling”

1. **Level of Exception Management**

   - In this non-professional sample, `DivideByNumber` only **throws exceptions** (e.g., `throw new ArgumentOutOfRangeException`) and does **not have any internal `catch` blocks**.  
   - In a professional approach, the function itself **catches predictable exceptions**, logs them, provides meaningful messages to the user, and optionally rethrows if needed.

2. **Reliance on `Main` for Handling**

   - Here, **all exception handling is delegated to `Main`**. Every error must be caught there to show proper feedback to the user.  
   - Professionally, each function is responsible for handling its **own predictable errors**, and only unexpected exceptions bubble up to `Main`.

3. **Readability and Maintainability**

   - When functions manage their specific exceptions, `Main` remains **clean and simple**.  
   - If all catches are in `Main`, the method becomes **long and cluttered** with error-handling logic.

4. **Logging and Debugging**

   - In professional code, each function can **log errors independently** without exposing technical details to the user.  
   - In this non-professional sample, detailed logging would require **extensive catch blocks in `Main`** and manually adding function context.

**In short:** Professional code makes each function “smart” to handle predictable errors itself, while `Main` only deals with **unexpected or unhandled exceptions**.


